[2024-11-17T08:47:06.789+0000] {local_task_job_runner.py:120} INFO - ::group::Pre task execution logs
[2024-11-17T08:47:06.801+0000] {taskinstance.py:2076} INFO - Dependencies all met for dep_context=non-requeueable deps ti=<TaskInstance: gcs_to_bq.dbt_run manual__2024-11-17T08:46:40.645848+00:00 [queued]>
[2024-11-17T08:47:06.807+0000] {taskinstance.py:2076} INFO - Dependencies all met for dep_context=requeueable deps ti=<TaskInstance: gcs_to_bq.dbt_run manual__2024-11-17T08:46:40.645848+00:00 [queued]>
[2024-11-17T08:47:06.808+0000] {taskinstance.py:2306} INFO - Starting attempt 1 of 1
[2024-11-17T08:47:06.822+0000] {taskinstance.py:2330} INFO - Executing <Task(BashOperator): dbt_run> on 2024-11-17 08:46:40.645848+00:00
[2024-11-17T08:47:06.827+0000] {standard_task_runner.py:63} INFO - Started process 2169 to run task
[2024-11-17T08:47:06.832+0000] {standard_task_runner.py:90} INFO - Running: ['airflow', 'tasks', 'run', 'gcs_to_bq', 'dbt_run', 'manual__2024-11-17T08:46:40.645848+00:00', '--job-id', '39', '--raw', '--subdir', 'DAGS_FOLDER/first.py', '--cfg-path', '/tmp/tmp_157yqom']
[2024-11-17T08:47:06.835+0000] {standard_task_runner.py:91} INFO - Job 39: Subtask dbt_run
[2024-11-17T08:47:06.879+0000] {task_command.py:426} INFO - Running <TaskInstance: gcs_to_bq.dbt_run manual__2024-11-17T08:46:40.645848+00:00 [running]> on host portfolio.us-central1-c.c.golden-centaur-440309-a9.internal
[2024-11-17T08:47:06.952+0000] {taskinstance.py:2648} INFO - Exporting env vars: AIRFLOW_CTX_DAG_OWNER='airflow' AIRFLOW_CTX_DAG_ID='gcs_to_bq' AIRFLOW_CTX_TASK_ID='dbt_run' AIRFLOW_CTX_EXECUTION_DATE='2024-11-17T08:46:40.645848+00:00' AIRFLOW_CTX_TRY_NUMBER='1' AIRFLOW_CTX_DAG_RUN_ID='manual__2024-11-17T08:46:40.645848+00:00'
[2024-11-17T08:47:06.953+0000] {taskinstance.py:430} INFO - ::endgroup::
[2024-11-17T08:47:06.966+0000] {subprocess.py:63} INFO - Tmp dir root location: /tmp
[2024-11-17T08:47:06.967+0000] {subprocess.py:75} INFO - Running command: ['/usr/bin/bash', '-c', 'cd /home/ghifariyadi_muhammad/my_dbt_project && dbt run']
[2024-11-17T08:47:06.978+0000] {subprocess.py:86} INFO - Output:
[2024-11-17T08:47:08.787+0000] {subprocess.py:93} INFO - [0m08:47:08  Running with dbt=1.8.8
[2024-11-17T08:47:10.174+0000] {subprocess.py:93} INFO - [0m08:47:10  Registered adapter: bigquery=1.8.3
[2024-11-17T08:47:10.500+0000] {subprocess.py:93} INFO - [0m08:47:10  Found 2 models, 4 data tests, 479 macros
[2024-11-17T08:47:10.503+0000] {subprocess.py:93} INFO - [0m08:47:10
[2024-11-17T08:47:11.125+0000] {subprocess.py:93} INFO - [0m08:47:11  Concurrency: 1 threads (target='dev')
[2024-11-17T08:47:11.126+0000] {subprocess.py:93} INFO - [0m08:47:11
[2024-11-17T08:47:11.130+0000] {subprocess.py:93} INFO - [0m08:47:11  1 of 2 START sql table model raw.nov_campaign .................................. [RUN]
[2024-11-17T08:47:13.782+0000] {subprocess.py:93} INFO - [0m08:47:13  1 of 2 OK created sql table model raw.nov_campaign ............................. [[32mCREATE TABLE (1.0 rows, 41.0 Bytes processed)[0m in 2.65s]
[2024-11-17T08:47:13.785+0000] {subprocess.py:93} INFO - [0m08:47:13  2 of 2 START sql view model raw.my_second_dbt_model ............................ [RUN]
[2024-11-17T08:47:15.482+0000] {subprocess.py:93} INFO - [0m08:47:15  BigQuery adapter: https://console.cloud.google.com/bigquery?project=golden-centaur-440309-a9&j=bq:US:9116aa8c-d3f7-41aa-8533-e2daf069f7ec&page=queryresults
[2024-11-17T08:47:15.493+0000] {subprocess.py:93} INFO - [0m08:47:15  2 of 2 ERROR creating sql view model raw.my_second_dbt_model ................... [[31mERROR[0m in 1.71s]
[2024-11-17T08:47:15.498+0000] {subprocess.py:93} INFO - [0m08:47:15
[2024-11-17T08:47:15.499+0000] {subprocess.py:93} INFO - [0m08:47:15  Finished running 1 table model, 1 view model in 0 hours 0 minutes and 4.99 seconds (4.99s).
[2024-11-17T08:47:15.546+0000] {subprocess.py:93} INFO - [0m08:47:15
[2024-11-17T08:47:15.546+0000] {subprocess.py:93} INFO - [0m08:47:15  [31mCompleted with 1 error and 0 warnings:[0m
[2024-11-17T08:47:15.547+0000] {subprocess.py:93} INFO - [0m08:47:15
[2024-11-17T08:47:15.548+0000] {subprocess.py:93} INFO - [0m08:47:15    Database Error in model my_second_dbt_model (models/example/my_second_dbt_model.sql)
[2024-11-17T08:47:15.548+0000] {subprocess.py:93} INFO -   Unrecognized name: id at [10:7]
[2024-11-17T08:47:15.548+0000] {subprocess.py:93} INFO -   compiled code at target/run/my_dbt_project/models/example/my_second_dbt_model.sql
[2024-11-17T08:47:15.548+0000] {subprocess.py:93} INFO - [0m08:47:15
[2024-11-17T08:47:15.549+0000] {subprocess.py:93} INFO - [0m08:47:15  Done. PASS=1 WARN=0 ERROR=1 SKIP=0 TOTAL=2
[2024-11-17T08:47:16.313+0000] {subprocess.py:97} INFO - Command exited with return code 1
[2024-11-17T08:47:16.314+0000] {taskinstance.py:441} INFO - ::group::Post task execution logs
[2024-11-17T08:47:16.322+0000] {taskinstance.py:2905} ERROR - Task failed with exception
Traceback (most recent call last):
  File "/home/ghifariyadi_muhammad/.venv/lib/python3.11/site-packages/airflow/models/taskinstance.py", line 465, in _execute_task
    result = _execute_callable(context=context, **execute_callable_kwargs)
             ^^^^^^^^^^^^^^^^^^^^^^^^^^^^^^^^^^^^^^^^^^^^^^^^^^^^^^^^^^^^^
  File "/home/ghifariyadi_muhammad/.venv/lib/python3.11/site-packages/airflow/models/taskinstance.py", line 432, in _execute_callable
    return execute_callable(context=context, **execute_callable_kwargs)
           ^^^^^^^^^^^^^^^^^^^^^^^^^^^^^^^^^^^^^^^^^^^^^^^^^^^^^^^^^^^^
  File "/home/ghifariyadi_muhammad/.venv/lib/python3.11/site-packages/airflow/models/baseoperator.py", line 401, in wrapper
    return func(self, *args, **kwargs)
           ^^^^^^^^^^^^^^^^^^^^^^^^^^^
  File "/home/ghifariyadi_muhammad/.venv/lib/python3.11/site-packages/airflow/operators/bash.py", line 243, in execute
    raise AirflowException(
airflow.exceptions.AirflowException: Bash command failed. The command returned a non-zero exit code 1.
[2024-11-17T08:47:16.327+0000] {taskinstance.py:1206} INFO - Marking task as FAILED. dag_id=gcs_to_bq, task_id=dbt_run, run_id=manual__2024-11-17T08:46:40.645848+00:00, execution_date=20241117T084640, start_date=20241117T084706, end_date=20241117T084716
[2024-11-17T08:47:16.341+0000] {standard_task_runner.py:110} ERROR - Failed to execute job 39 for task dbt_run (Bash command failed. The command returned a non-zero exit code 1.; 2169)
[2024-11-17T08:47:16.357+0000] {local_task_job_runner.py:240} INFO - Task exited with return code 1
[2024-11-17T08:47:16.367+0000] {taskinstance.py:3503} INFO - 0 downstream tasks scheduled from follow-on schedule check
[2024-11-17T08:47:16.368+0000] {local_task_job_runner.py:222} INFO - ::endgroup::
