[2024-11-27T14:36:34.332+0000] {local_task_job_runner.py:120} INFO - ::group::Pre task execution logs
[2024-11-27T14:36:34.343+0000] {taskinstance.py:2076} INFO - Dependencies all met for dep_context=non-requeueable deps ti=<TaskInstance: gcs_to_bq.product scheduled__2024-11-26T00:00:00+00:00 [queued]>
[2024-11-27T14:36:34.349+0000] {taskinstance.py:2076} INFO - Dependencies all met for dep_context=requeueable deps ti=<TaskInstance: gcs_to_bq.product scheduled__2024-11-26T00:00:00+00:00 [queued]>
[2024-11-27T14:36:34.349+0000] {taskinstance.py:2306} INFO - Starting attempt 2 of 2
[2024-11-27T14:36:34.362+0000] {taskinstance.py:2330} INFO - Executing <Task(GCSToBigQueryOperator): product> on 2024-11-26 00:00:00+00:00
[2024-11-27T14:36:34.367+0000] {standard_task_runner.py:63} INFO - Started process 1008 to run task
[2024-11-27T14:36:34.374+0000] {standard_task_runner.py:90} INFO - Running: ['airflow', 'tasks', 'run', 'gcs_to_bq', 'product', 'scheduled__2024-11-26T00:00:00+00:00', '--job-id', '46', '--raw', '--subdir', 'DAGS_FOLDER/first.py', '--cfg-path', '/tmp/tmpvyjeudhj']
[2024-11-27T14:36:34.377+0000] {standard_task_runner.py:91} INFO - Job 46: Subtask product
[2024-11-27T14:36:34.421+0000] {task_command.py:426} INFO - Running <TaskInstance: gcs_to_bq.product scheduled__2024-11-26T00:00:00+00:00 [running]> on host portfolio.us-central1-c.c.golden-centaur-440309-a9.internal
[2024-11-27T14:36:34.483+0000] {taskinstance.py:2648} INFO - Exporting env vars: AIRFLOW_CTX_DAG_OWNER='airflow' AIRFLOW_CTX_DAG_ID='gcs_to_bq' AIRFLOW_CTX_TASK_ID='product' AIRFLOW_CTX_EXECUTION_DATE='2024-11-26T00:00:00+00:00' AIRFLOW_CTX_TRY_NUMBER='2' AIRFLOW_CTX_DAG_RUN_ID='scheduled__2024-11-26T00:00:00+00:00'
[2024-11-27T14:36:34.484+0000] {taskinstance.py:430} INFO - ::endgroup::
[2024-11-27T14:36:34.501+0000] {connection.py:274} WARNING - Connection schemes (type: google_cloud_platform) shall not contain '_' according to RFC3986.
[2024-11-27T14:36:34.502+0000] {base.py:84} INFO - Using connection ID 'google_cloud_default' for task execution.
[2024-11-27T14:36:34.503+0000] {gcs_to_bigquery.py:380} INFO - Using existing BigQuery table for storing data...
[2024-11-27T14:36:34.554+0000] {gcs_to_bigquery.py:384} INFO - Executing: {'load': {'autodetect': True, 'createDisposition': 'CREATE_IF_NEEDED', 'destinationTable': {'projectId': 'golden-centaur-440309-a9', 'datasetId': 'raw', 'tableId': 'product'}, 'sourceFormat': 'CSV', 'sourceUris': ['gs://ghif_portfolio/sales_data - product.csv'], 'writeDisposition': 'WRITE_TRUNCATE', 'ignoreUnknownValues': False, 'skipLeadingRows': None, 'fieldDelimiter': ',', 'quote': None, 'allowQuotedNewlines': False, 'encoding': 'UTF-8'}}
[2024-11-27T14:36:34.556+0000] {bigquery.py:1660} INFO - Inserting job airflow_gcs_to_bq_product_2024_11_26T00_00_00_00_00_0c63ee466f206d4eb7156095e6874cf4
[2024-11-27T14:36:34.628+0000] {taskinstance.py:441} INFO - ::group::Post task execution logs
[2024-11-27T14:36:34.629+0000] {taskinstance.py:2905} ERROR - Task failed with exception
Traceback (most recent call last):
  File "/home/ghifariyadi_muhammad/.venv/lib/python3.11/site-packages/airflow/models/taskinstance.py", line 465, in _execute_task
    result = _execute_callable(context=context, **execute_callable_kwargs)
             ^^^^^^^^^^^^^^^^^^^^^^^^^^^^^^^^^^^^^^^^^^^^^^^^^^^^^^^^^^^^^
  File "/home/ghifariyadi_muhammad/.venv/lib/python3.11/site-packages/airflow/models/taskinstance.py", line 432, in _execute_callable
    return execute_callable(context=context, **execute_callable_kwargs)
           ^^^^^^^^^^^^^^^^^^^^^^^^^^^^^^^^^^^^^^^^^^^^^^^^^^^^^^^^^^^^
  File "/home/ghifariyadi_muhammad/.venv/lib/python3.11/site-packages/airflow/models/baseoperator.py", line 401, in wrapper
    return func(self, *args, **kwargs)
           ^^^^^^^^^^^^^^^^^^^^^^^^^^^
  File "/home/ghifariyadi_muhammad/.venv/lib/python3.11/site-packages/airflow/providers/google/cloud/transfers/gcs_to_bigquery.py", line 385, in execute
    job: BigQueryJob | UnknownJob = self._submit_job(self.hook, job_id)
                                    ^^^^^^^^^^^^^^^^^^^^^^^^^^^^^^^^^^^
  File "/home/ghifariyadi_muhammad/.venv/lib/python3.11/site-packages/airflow/providers/google/cloud/transfers/gcs_to_bigquery.py", line 307, in _submit_job
    return hook.insert_job(
           ^^^^^^^^^^^^^^^^
  File "/home/ghifariyadi_muhammad/.venv/lib/python3.11/site-packages/airflow/providers/google/common/hooks/base_google.py", line 486, in inner_wrapper
    return func(self, *args, **kwargs)
           ^^^^^^^^^^^^^^^^^^^^^^^^^^^
  File "/home/ghifariyadi_muhammad/.venv/lib/python3.11/site-packages/airflow/providers/google/cloud/hooks/bigquery.py", line 1663, in insert_job
    job_api_repr._begin()
  File "/home/ghifariyadi_muhammad/.venv/lib/python3.11/site-packages/google/cloud/bigquery/job/base.py", line 746, in _begin
    api_response = client._call_api(
                   ^^^^^^^^^^^^^^^^^
  File "/home/ghifariyadi_muhammad/.venv/lib/python3.11/site-packages/google/cloud/bigquery/client.py", line 833, in _call_api
    return call()
           ^^^^^^
  File "/home/ghifariyadi_muhammad/.venv/lib/python3.11/site-packages/google/api_core/retry/retry_unary.py", line 293, in retry_wrapped_func
    return retry_target(
           ^^^^^^^^^^^^^
  File "/home/ghifariyadi_muhammad/.venv/lib/python3.11/site-packages/google/api_core/retry/retry_unary.py", line 153, in retry_target
    _retry_error_helper(
  File "/home/ghifariyadi_muhammad/.venv/lib/python3.11/site-packages/google/api_core/retry/retry_base.py", line 212, in _retry_error_helper
    raise final_exc from source_exc
  File "/home/ghifariyadi_muhammad/.venv/lib/python3.11/site-packages/google/api_core/retry/retry_unary.py", line 144, in retry_target
    result = target()
             ^^^^^^^^
  File "/home/ghifariyadi_muhammad/.venv/lib/python3.11/site-packages/google/cloud/_http/__init__.py", line 482, in api_request
    response = self._make_request(
               ^^^^^^^^^^^^^^^^^^^
  File "/home/ghifariyadi_muhammad/.venv/lib/python3.11/site-packages/google/cloud/_http/__init__.py", line 341, in _make_request
    return self._do_request(
           ^^^^^^^^^^^^^^^^^
  File "/home/ghifariyadi_muhammad/.venv/lib/python3.11/site-packages/google/cloud/_http/__init__.py", line 379, in _do_request
    return self.http.request(
           ^^^^^^^^^^^^^^^^^^
  File "/home/ghifariyadi_muhammad/.venv/lib/python3.11/site-packages/google/auth/transport/requests.py", line 534, in request
    self.credentials.before_request(auth_request, method, url, request_headers)
  File "/home/ghifariyadi_muhammad/.venv/lib/python3.11/site-packages/google/auth/credentials.py", line 239, in before_request
    self._blocking_refresh(request)
  File "/home/ghifariyadi_muhammad/.venv/lib/python3.11/site-packages/google/auth/credentials.py", line 202, in _blocking_refresh
    self.refresh(request)
  File "/home/ghifariyadi_muhammad/.venv/lib/python3.11/site-packages/google/oauth2/service_account.py", line 448, in refresh
    access_token, expiry, _ = _client.jwt_grant(
                              ^^^^^^^^^^^^^^^^^^
  File "/home/ghifariyadi_muhammad/.venv/lib/python3.11/site-packages/google/oauth2/_client.py", line 298, in jwt_grant
    response_data = _token_endpoint_request(
                    ^^^^^^^^^^^^^^^^^^^^^^^^
  File "/home/ghifariyadi_muhammad/.venv/lib/python3.11/site-packages/google/oauth2/_client.py", line 269, in _token_endpoint_request
    _handle_error_response(response_data, retryable_error)
  File "/home/ghifariyadi_muhammad/.venv/lib/python3.11/site-packages/google/oauth2/_client.py", line 68, in _handle_error_response
    raise exceptions.RefreshError(
google.auth.exceptions.RefreshError: ('invalid_grant: Invalid JWT Signature.', {'error': 'invalid_grant', 'error_description': 'Invalid JWT Signature.'})
[2024-11-27T14:36:34.637+0000] {taskinstance.py:1206} INFO - Marking task as FAILED. dag_id=gcs_to_bq, task_id=product, run_id=scheduled__2024-11-26T00:00:00+00:00, execution_date=20241126T000000, start_date=20241127T143634, end_date=20241127T143634
[2024-11-27T14:36:34.648+0000] {standard_task_runner.py:110} ERROR - Failed to execute job 46 for task product (('invalid_grant: Invalid JWT Signature.', {'error': 'invalid_grant', 'error_description': 'Invalid JWT Signature.'}); 1008)
[2024-11-27T14:36:34.666+0000] {local_task_job_runner.py:240} INFO - Task exited with return code 1
[2024-11-27T14:36:34.686+0000] {taskinstance.py:3503} INFO - 0 downstream tasks scheduled from follow-on schedule check
[2024-11-27T14:36:34.692+0000] {local_task_job_runner.py:222} INFO - ::endgroup::
