[2024-11-12T07:32:45.738+0000] {local_task_job_runner.py:120} INFO - ::group::Pre task execution logs
[2024-11-12T07:32:45.752+0000] {taskinstance.py:2076} INFO - Dependencies all met for dep_context=non-requeueable deps ti=<TaskInstance: gcs_to_bq.gcs_to_bq scheduled__2024-11-11T00:00:00+00:00 [queued]>
[2024-11-12T07:32:45.759+0000] {taskinstance.py:2076} INFO - Dependencies all met for dep_context=requeueable deps ti=<TaskInstance: gcs_to_bq.gcs_to_bq scheduled__2024-11-11T00:00:00+00:00 [queued]>
[2024-11-12T07:32:45.759+0000] {taskinstance.py:2306} INFO - Starting attempt 2 of 2
[2024-11-12T07:32:45.777+0000] {taskinstance.py:2330} INFO - Executing <Task(GCSToBigQueryOperator): gcs_to_bq> on 2024-11-11 00:00:00+00:00
[2024-11-12T07:32:45.783+0000] {standard_task_runner.py:63} INFO - Started process 1076 to run task
[2024-11-12T07:32:45.790+0000] {standard_task_runner.py:90} INFO - Running: ['airflow', 'tasks', 'run', 'gcs_to_bq', 'gcs_to_bq', 'scheduled__2024-11-11T00:00:00+00:00', '--job-id', '11', '--raw', '--subdir', 'DAGS_FOLDER/first.py', '--cfg-path', '/tmp/tmplm2lf_iv']
[2024-11-12T07:32:45.793+0000] {standard_task_runner.py:91} INFO - Job 11: Subtask gcs_to_bq
[2024-11-12T07:32:45.845+0000] {task_command.py:426} INFO - Running <TaskInstance: gcs_to_bq.gcs_to_bq scheduled__2024-11-11T00:00:00+00:00 [running]> on host portfolio.us-central1-c.c.golden-centaur-440309-a9.internal
[2024-11-12T07:32:45.918+0000] {taskinstance.py:2648} INFO - Exporting env vars: AIRFLOW_CTX_DAG_OWNER='airflow' AIRFLOW_CTX_DAG_ID='gcs_to_bq' AIRFLOW_CTX_TASK_ID='gcs_to_bq' AIRFLOW_CTX_EXECUTION_DATE='2024-11-11T00:00:00+00:00' AIRFLOW_CTX_TRY_NUMBER='2' AIRFLOW_CTX_DAG_RUN_ID='scheduled__2024-11-11T00:00:00+00:00'
[2024-11-12T07:32:45.920+0000] {taskinstance.py:430} INFO - ::endgroup::
[2024-11-12T07:32:45.937+0000] {connection.py:274} WARNING - Connection schemes (type: google_cloud_platform) shall not contain '_' according to RFC3986.
[2024-11-12T07:32:45.939+0000] {base.py:84} INFO - Using connection ID 'google_cloud_default' for task execution.
[2024-11-12T07:32:45.940+0000] {gcs_to_bigquery.py:380} INFO - Using existing BigQuery table for storing data...
[2024-11-12T07:32:45.995+0000] {gcs_to_bigquery.py:384} INFO - Executing: {'load': {'autodetect': True, 'createDisposition': 'CREATE_IF_NEEDED', 'destinationTable': {'projectId': 'golden-centaur-440309-a9', 'datasetId': 'raw', 'tableId': 'sales'}, 'sourceFormat': 'NEWLINE_DELIMITED_JSON', 'sourceUris': ['gs://ghif_portfolio/sales_data_example.csv'], 'writeDisposition': 'WRITE_TRUNCATE', 'ignoreUnknownValues': False}}
[2024-11-12T07:32:45.996+0000] {bigquery.py:1660} INFO - Inserting job airflow_gcs_to_bq_gcs_to_bq_2024_11_11T00_00_00_00_00_aca3fca780ea87082efabc467ac25ef0
[2024-11-12T07:32:46.989+0000] {taskinstance.py:441} INFO - ::group::Post task execution logs
[2024-11-12T07:32:46.990+0000] {taskinstance.py:2905} ERROR - Task failed with exception
Traceback (most recent call last):
  File "/home/ghifariyadi_muhammad/.venv/lib/python3.11/site-packages/airflow/models/taskinstance.py", line 465, in _execute_task
    result = _execute_callable(context=context, **execute_callable_kwargs)
             ^^^^^^^^^^^^^^^^^^^^^^^^^^^^^^^^^^^^^^^^^^^^^^^^^^^^^^^^^^^^^
  File "/home/ghifariyadi_muhammad/.venv/lib/python3.11/site-packages/airflow/models/taskinstance.py", line 432, in _execute_callable
    return execute_callable(context=context, **execute_callable_kwargs)
           ^^^^^^^^^^^^^^^^^^^^^^^^^^^^^^^^^^^^^^^^^^^^^^^^^^^^^^^^^^^^
  File "/home/ghifariyadi_muhammad/.venv/lib/python3.11/site-packages/airflow/models/baseoperator.py", line 401, in wrapper
    return func(self, *args, **kwargs)
           ^^^^^^^^^^^^^^^^^^^^^^^^^^^
  File "/home/ghifariyadi_muhammad/.venv/lib/python3.11/site-packages/airflow/providers/google/cloud/transfers/gcs_to_bigquery.py", line 445, in execute
    job.result(timeout=self.result_timeout, retry=self.result_retry)
  File "/home/ghifariyadi_muhammad/.venv/lib/python3.11/site-packages/google/cloud/bigquery/job/base.py", line 969, in result
    return super(_AsyncJob, self).result(timeout=timeout, **kwargs)
           ^^^^^^^^^^^^^^^^^^^^^^^^^^^^^^^^^^^^^^^^^^^^^^^^^^^^^^^^
  File "/home/ghifariyadi_muhammad/.venv/lib/python3.11/site-packages/google/api_core/future/polling.py", line 261, in result
    raise self._exception
google.api_core.exceptions.Forbidden: 403 Access Denied: File gs://ghif_portfolio/sales_data_example.csv: Access Denied; reason: accessDenied, message: Access Denied: File gs://ghif_portfolio/sales_data_example.csv: Access Denied
[2024-11-12T07:32:46.998+0000] {taskinstance.py:1206} INFO - Marking task as FAILED. dag_id=gcs_to_bq, task_id=gcs_to_bq, run_id=scheduled__2024-11-11T00:00:00+00:00, execution_date=20241111T000000, start_date=20241112T073245, end_date=20241112T073246
[2024-11-12T07:32:47.013+0000] {standard_task_runner.py:110} ERROR - Failed to execute job 11 for task gcs_to_bq (403 Access Denied: File gs://ghif_portfolio/sales_data_example.csv: Access Denied; reason: accessDenied, message: Access Denied: File gs://ghif_portfolio/sales_data_example.csv: Access Denied; 1076)
[2024-11-12T07:32:47.046+0000] {local_task_job_runner.py:240} INFO - Task exited with return code 1
[2024-11-12T07:32:47.065+0000] {taskinstance.py:3503} INFO - 0 downstream tasks scheduled from follow-on schedule check
[2024-11-12T07:32:47.066+0000] {local_task_job_runner.py:222} INFO - ::endgroup::
